Traceback (most recent call last):
  File "/Users/tchun/opt/anaconda3/envs/class_ml/lib/python3.12/site-packages/jupyter_cache/executors/utils.py", line 58, in single_nb_execution
    executenb(
  File "/Users/tchun/opt/anaconda3/envs/class_ml/lib/python3.12/site-packages/nbclient/client.py", line 1305, in execute
    return NotebookClient(nb=nb, resources=resources, km=km, **kwargs).execute()
           ^^^^^^^^^^^^^^^^^^^^^^^^^^^^^^^^^^^^^^^^^^^^^^^^^^^^^^^^^^^^^^^^^^^^^
  File "/Users/tchun/opt/anaconda3/envs/class_ml/lib/python3.12/site-packages/jupyter_core/utils/__init__.py", line 165, in wrapped
    return loop.run_until_complete(inner)
           ^^^^^^^^^^^^^^^^^^^^^^^^^^^^^^
  File "/Users/tchun/opt/anaconda3/envs/class_ml/lib/python3.12/asyncio/base_events.py", line 687, in run_until_complete
    return future.result()
           ^^^^^^^^^^^^^^^
  File "/Users/tchun/opt/anaconda3/envs/class_ml/lib/python3.12/site-packages/nbclient/client.py", line 705, in async_execute
    await self.async_execute_cell(
  File "/Users/tchun/opt/anaconda3/envs/class_ml/lib/python3.12/site-packages/nbclient/client.py", line 1058, in async_execute_cell
    await self._check_raise_for_error(cell, cell_index, exec_reply)
  File "/Users/tchun/opt/anaconda3/envs/class_ml/lib/python3.12/site-packages/nbclient/client.py", line 914, in _check_raise_for_error
    raise CellExecutionError.from_cell_and_msg(cell, exec_reply_content)
nbclient.exceptions.CellExecutionError: An error occurred while executing the following cell:
------------------
import numpy as np
import pandas as pd
import random

import matplotlib.pyplot as plt
from matplotlib.pylab import rcParams
rcParams['figure.figsize'] = 12, 10

# Create x values
x = np.array([i*np.pi/180 for i in range(60,300,4)])
np.random.seed(10)  # Setting seed for reproducibility

# Use cosine function instead of sine
y = np.cos(x) + np.random.normal(0,0.15,len(x))

# Create a dataframe
data = pd.DataFrame(np.column_stack([x, y]), columns=['x', 'y'])

# Plot the data
plt.plot(data['x'], data['y'], '.')
plt.show()
------------------


[0;31m---------------------------------------------------------------------------[0m
[0;31mModuleNotFoundError[0m                       Traceback (most recent call last)
Cell [0;32mIn[1], line 5[0m
[1;32m      2[0m [38;5;28;01mimport[39;00m [38;5;21;01mpandas[39;00m [38;5;28;01mas[39;00m [38;5;21;01mpd[39;00m
[1;32m      3[0m [38;5;28;01mimport[39;00m [38;5;21;01mrandom[39;00m
[0;32m----> 5[0m [38;5;28;01mimport[39;00m [38;5;21;01mmatplotlib[39;00m[38;5;21;01m.[39;00m[38;5;21;01mpyplot[39;00m [38;5;28;01mas[39;00m [38;5;21;01mplt[39;00m
[1;32m      6[0m [38;5;28;01mfrom[39;00m [38;5;21;01mmatplotlib[39;00m[38;5;21;01m.[39;00m[38;5;21;01mpylab[39;00m [38;5;28;01mimport[39;00m rcParams
[1;32m      7[0m rcParams[[38;5;124m'[39m[38;5;124mfigure.figsize[39m[38;5;124m'[39m] [38;5;241m=[39m [38;5;241m12[39m, [38;5;241m10[39m

[0;31mModuleNotFoundError[0m: No module named 'matplotlib'

